Workbook

Sheet Company 01-01-21 to 31-12-25
A1: Date | B1: Open Price | C1: High Price | D1: Low Price | E1: Close Price | F1: WAP | G1: No.of Shares | H1: No. of Trades | I1: Total Turnover (Rs.) | J1: Deliverable Quantity | K1: % Deli. Qty to Traded Qty | L1: Spread High-Low | M1: Spread Close-Open
A2: 44197 | B2: 33 | C2: 33.9 | D2: 33 | E2: 33.1 | F2: 33.279063 | G2: 14219 | H2: 72 | I2: 473195 | J2: 9315 | K2: 65.51 | L2: 0.9 | M2: 0.1
A3: 44200 | B3: 33.9 | C3: 34 | D3: 32 | E3: 32.2 | F3: 33.048506 | G3: 26471 | H3: 103 | I3: 874827 | J3: 21948 | K3: 82.91 | L3: 2 | M3: -1.7
A4: 44201 | B4: 32.2 | C4: 32.95 | D4: 31.1 | E4: 31.95 | F4: 32.168497 | G4: 25496 | H4: 69 | I4: 820168 | J4: 23428 | K4: 91.89 | L4: 1.85 | M4: -0.25
A5: 44202 | B5: 31.95 | C5: 32.3 | D5: 30.5 | E5: 30.9 | F5: 31.260404 | G5: 17469 | H5: 75 | I5: 546088 | J5: 15016 | K5: 85.96 | L5: 1.8 | M5: -1.05
A6: 44203 | B6: 32 | C6: 35.9 | D6: 29.15 | E6: 33.9 | F6: 33.26711 | G6: 213878 | H6: 861 | I6: 7115103 | J6: 96814 | K6: 45.27 | L6: 6.75 | M6: 1.9
A7: 44204 | B7: 35.5 | C7: 35.6 | D7: 32.2 | E7: 33.05 | F7: 34.356203 | G7: 29938 | H7: 223 | I7: 1028556 | J7: 22424 | K7: 74.9 | L7: 3.4 | M7: -2.45
A8: 44207 | B8: 34.95 | C8: 35 | D8: 32.5 | E8: 32.85 | F8: 33.556155 | G8: 26525 | H8: 165 | I8: 890077 | J8: 19887 | K8: 74.97 | L8: 2.5 | M8: -2.1
A9: 44208 | B9: 32 | C9: 32.65 | D9: 31.25 | E9: 32.05 | F9: 32.061391 | G9: 13471 | H9: 71 | I9: 431899 | J9: 12322 | K9: 91.47 | L9: 1.4 | M9: 0.05
A10: 44209 | B10: 31.45 | C10: 32.25 | D10: 31 | E10: 31.2 | F10: 31.447238 | G10: 17778 | H10: 87 | I10: 559069 | J10: 16055 | K10: 90.31 | L10: 1.25 | M10: -0.25
A11: 44210 | B11: 32.4 | C11: 32.4 | D11: 28.35 | E11: 29.75 | F11: 30.154581 | G11: 19776 | H11: 134 | I11: 596337 | J11: 18350 | K11: 92.79 | L11: 4.05 | M11: -2.65
A12: 44211 | B12: 27.2 | C12: 29.5 | D12: 27.2 | E12: 29.25 | F12: 28.817923 | G12: 13357 | H12: 56 | I12: 384921 | J12: 12457 | K12: 93.26 | L12: 2.3 | M12: 2.05
A13: 44214 | B13: 29 | C13: 29.9 | D13: 29 | E13: 29.1 | F13: 29.245861 | G13: 9965 | H13: 47 | I13: 291435 | J13: 9265 | K13: 92.98 | L13: 0.9 | M13: 0.1
... A1241: 46022 | B1241: 335 | C1241: 335.95 | D1241: 331.8 | E1241: 334 | F1241: 334.22231 | G1241: 4026 | H1241: 286 | I1241: 1345579 | J1241: 2406 | K1241: 59.76 | L1241: 4.15 | M1241: -1

Sheet Market 01-01-21 to 31-12-25
A1: Date | B1: Open | C1: High | D1: Low | E1: Close | F1: Points Change | G1: Change(%) | H1: Volume(Cr.) | I1: Turnover (Rs.Cr.) | J1: P/E | K1: P/B | L1: Div Yield
A2: 44197 | B2: 47785.28 | C2: 47980.36 | D2: 47771.15 | E2: 47868.98 | F2: 117.65 | G2: 0.25 | H2: 0.83 | I2: 524.96 | J2: 33.5 | K2: 3.27 | L2: 0.83
A3: 44200 | B3: 48109.17 | C3: 48220.47 | D3: 47594.47 | E3: 48176.8 | F3: 307.82 | G3: 0.64 | H3: 1.39 | I3: 809.27 | J3: 33.68 | K3: 3.29 | L3: 0.82
A4: 44201 | B4: 48037.63 | C4: 48486.24 | D4: 47903.38 | E4: 48437.78 | F4: 260.98 | G4: 0.54 | H4: 1.22 | I4: 932.63 | J4: 33.76 | K4: 3.3 | L4: 0.82
A5: 44202 | B5: 48616.66 | C5: 48616.66 | D5: 47864.14 | E5: 48174.06 | F5: -263.72 | G5: -0.54 | H5: - | J5: 33.59 | K5: 3.28 | L5: 0.83
A6: 44203 | B6: 48524.36 | C6: 48558.34 | D6: 48037.87 | E6: 48093.32 | F6: -80.74 | G6: -0.17 | H6: 1.84 | I6: 1417.49 | J6: 33.51 | K6: 3.27 | L6: 0.83
A7: 44204 | B7: 48464.91 | C7: 48854.34 | D7: 48365.58 | E7: 48782.51 | F7: 689.19 | G7: 1.43 | H7: 2.22 | I7: 1716.24 | J7: 33.93 | K7: 3.31 | L7: 0.82
A8: 44207 | B8: 49252.31 | C8: 49303.79 | D8: 48956.38 | E8: 49269.32 | F8: 486.81 | G8: 1 | H8: 2.12 | I8: 1605.22 | J8: 34.32 | K8: 3.37 | L8: 0.81
A9: 44208 | B9: 49228.26 | C9: 49569.14 | D9: 49079.57 | E9: 49517.11 | F9: 247.79 | G9: 0.5 | H9: 1.27 | I9: 940.52 | J9: 34.55 | K9: 3.39 | L9: 0.8
A10: 44209 | B10: 49763.93 | C10: 49795.19 | D10: 49073.85 | E10: 49492.32 | F10: -24.79 | G10: -0.05 | H10: 2.72 | I10: 1611.31 | J10: 34.65 | K10: 3.4 | L10: 0.8
A11: 44210 | B11: 49432.83 | C11: 49663.58 | D11: 49182.37 | E11: 49584.16 | F11: 91.84 | G11: 0.19 | H11: - | J11: 34.63 | K11: 3.4 | L11: 0.8
A12: 44211 | B12: 49656.71 | C12: 49656.71 | D12: 48795.79 | E12: 49034.67 | F12: -549.49 | G12: -1.11 | H12: 1.47 | I12: 1266.97 | J12: 34.12 | K12: 3.35 | L12: 0.81
A13: 44214 | B13: 49061.22 | C13: 49122.23 | D13: 48403.97 | E13: 48564.27 | F13: -470.4 | G13: -0.96 | H13: 1.66 | I13: 1187.8 | J13: 33.47 | K13: 3.3 | L13: 0.82
A14: 44215 | B14: 48900.31 | C14: 49499.86 | D14: 48805.54 | E14: 49398.29 | F14: 834.02 | G14: 1.72 | H14: - | J14: 34.08 | K14: 3.36 | L14: 0.81
A15: 44216 | B15: 49508.79 | C15: 49874.42 | D15: 49373.68 | E15: 49792.12 | F15: 393.83 | G15: 0.8 | H15: 1.22 | I15: 1402.16 | J15: 34.42 | K15: 3.39 | L15: 0.8
A16: 44217 | B16: 50096.57 | C16: 50184.01 | D16: 49398.86 | E16: 49624.76 | F16: -167.36 | G16: -0.34 | H16: 1.93 | I16: 1709.66 | J16: 34.36 | K16: 3.38 | L16: 0.8
A17: 44218 | B17: 49594.95 | C17: 49676.88 | D17: 48832.08 | E17: 48878.54 | F17: -746.22 | G17: -1.5 | H17: 1.84 | I17: 1486.69 | J17: 33.76 | K17: 3.32 | L17: 0.81
A18: 44221 | B18: 49253.68 | C18: 49263.15 | D18: 48274.92 | E18: 48347.59 | F18: -530.95 | G18: -1.09 | H18: 1.55 | I18: 1432.04 | J18: 33.13 | K18: 3.29 | L18: 0.82
A19: 44223 | B19: 48385.28 | C19: 48387.25 | D19: 47269.6 | E19: 47409.93 | F19: -937.66 | G19: -1.94 | H19: 1.96 | I19: 1444.17 | J19: 32.46 | K19: 3.23 | L19: 0.84
A20: 44224 | B20: 46834.57 | C20: 47172.02 | D20: 46518.48 | E20: 46874.36 | F20: -535.57 | G20: -1.13 | H20: 2.5 | I20: 2471.27 | J20: 31.96 | K20: 3.18 | L20: 0.85
A21: 44225 | B21: 47423.47 | C21: 47423.66 | D21: 46160.46 | E21: 46285.77 | F21: -588.59 | G21: -1.26 | H21: 1.45 | I21: 1155.6 | J21: 31.75 | K21: 3.15 | L21: 0.86
A22: 44228 | B22: 46617.95 | C22: 48764.4 | D22: 46433.65 | E22: 48600.61 | F22: 2314.84 | G22: 5 | H22: 2.2 | I22: 1754.31 | J22: 33.08 | K22: 3.3 | L22: 0.82
A23: 44229 | B23: 49193.26 | C23: 50154.48 | D23: 49193.26 | E23: 49797.72 | F23: 1197.11 | G23: 2.46 | H23: 2.84 | I23: 2138.24 | J23: 33.92 | K23: 3.38 | L23: 0.8
A24: 44230 | B24: 50231.06 | C24: 50526.39 | D24: 49515.88 | E24: 50255.75 | F24: 458.03 | G24: 0.92 | H24: 2.24 | I24: 1511.42 | J24: 34.15 | K24: 3.41 | L24: 0.79
A25: 44231 | B25: 50212.25 | C25: 50687.51 | D25: 49926.45 | E25: 50614.29 | F25: 358.54 | G25: 0.71 | H25: 3.36 | I25: 2663.16 | J25: 34.42 | K25: 3.43 | L25: 0.79
A26: 44232 | B26: 51031.39 | C26: 51073.27 | D26: 50565.29 | E26: 50731.63 | F26: 117.34 | G26: 0.23 | H26: 3.22 | I26: 1869.14 | J26: 34.26 | K26: 3.43 | L26: 0.79
... A30: 44238 | B30: 51165.84 | C30: 51592.45 | D30: 51157.31 | E30: 51531.52 | F30: 222.13 | G30: 0.43 | H30: 1.21 | I30: 1131.41 | J30: 35.8 | K30: 3.48 | L30: 0.79
A31: 44239 | B31: 51614.77 | C31: 51804.58 | D31: 51260.62 | E31: 51544.3 | F31: 12.78 | G31: 0.02 | H31: - | J31: 35.79 | K31: 3.48 | L31: 0.79
A32: 44242 | B32: 51907.75 | C32: 52235.97 | D32: 51886.46 | E32: 52154.13 | F32: 609.83 | G32: 1.18 | H32: 1.47 | I32: 1078.13 | J32: 36.21 | K32: 3.52 | L32: 0.71
A33: 44243 | B33: 52400.03 | C33: 52516.76 | D33: 51863.61 | E33: 52104.17 | F33: -49.96 | G33: -0.1 | H33: 2.11 | I33: 1248.34 | J33: 36.13 | K33: 3.51 | L33: 0.71
A34: 44244 | B34: 51996.94 | C34: 52078.15 | D34: 51586.34 | E34: 51703.83 | F34: -400.34 | G34: -0.77 | H34: 1.36 | I34: 1111.59 | J34: 36.01 | K34: 3.49 | L34: 0.69
A35: 44245 | B35: 51903.96 | C35: 51903.96 | D35: 51186.68 | E35: 51324.69 | F35: -379.14 | G35: -0.73 | H35: 1.82 | I35: 1046.63 | J35: 35.9 | K35: 3.48 | L35: 0.7
A36: 44246 | B36: 51238.02 | C36: 51432.99 | D36: 50624.33 | E36: 50889.76 | F36: -434.93 | G36: -0.85 | H36: 1.5 | I36: 961.98 | J36: 35.64 | K36: 3.45 | L36: 0.7
A37: 44249 | B37: 50910.51 | C37: 50986.03 | D37: 49617.37 | E37: 49744.32 | F37: -1145.44 | G37: -2.25 | H37: 1.63 | I37: 1111.76 | J37: 34.76 | K37: 3.37 | L37: 0.72
A38: 44250 | B38: 49994.85 | C38: 50327.31 | D38: 49659.85 | E38: 49751.41 | F38: 7.09 | G38: 0.01 | H38: - | J38: 34.79 | K38: 3.37 | L38: 0.72
A39: 44251 | B39: 49763.94 | C39: 50881.17 | D39: 49648.78 | E39: 50781.69 | F39: 1030.28 | G39: 2.07 | H39: 4.59 | I39: 3805.89 | J39: 35.46 | K39: 3.43 | L39: 0.71
A40: 44252 | B40: 51207.61 | C40: 51386.12 | D40: 50991.76 | E40: 51039.31 | F40: 257.62 | G40: 0.51 | H40: 3.35 | I40: 2624.1 | J40: 35.6 | K40: 3.45 | L40: 0.7
A41: 44253 | B41: 50256.71 | C41: 50400.31 | D41: 48890.48 | E41: 49099.99 | F41: -1939.32 | G41: -3.8 | H41: 2.31 | I41: 1634.09 | J41: 33.86 | K41: 3.28 | L41: 0.74
A42: 44256 | B42: 49747.71 | C42: 50058.42 | D42: 49440.46 | E42: 49849.84 | F42: 749.85 | G42: 1.53 | H42: 1.84 | I42: 1193.06 | J42: 34.79 | K42: 3.37 | L42: 0.72
A43: 44257 | B43: 50258.09 | C43: 50439.82 | D43: 49807.12 | E43: 50296.89 | F43: 447.05 | G43: 0.9 | H43: 1.75 | I43: 983.62 | J43: 35.12 | K43: 3.4 | L43: 0.71
...

Sheet Stock Returns
A1: Date | B1: Close Price | C1: Daily Stock Returns | D1: Daily Stock Returns% | O1: Date | P1: Close Price | Q1: Daily Market Returns | R1: Daily Market Returns%
A2: 44197 | B2: 33.1 | C2: - | D2: - | O2: 44197 | P2: 47868.98 | Q2: -
A3: 44200 | B3: 32.2 | C3: =(B3-B2)/B2 -> -0.027190332 | D3: =(B3-B2)/B2 -> -0.027190332 | O3: 44200 | P3: 48176.8 | Q3: =(P3-P2)/P2 -> 0.0064304692 | R3: =(P3-P2)/P2 -> 0.0064304692 | U3: Returns | V3: Returns%
A4: 44201 | B4: 31.95 | C4: =(B4-B3)/B3 -> -0.0077639752 | D4: =(B4-B3)/B3 -> -0.0077639752 | F4: Returns | G4: Returns% | O4: 44201 | P4: 48437.78 | Q4: =(P4-P3)/P3 -> 0.0054171302 | R4: =(P4-P3)/P3 -> 0.0054171302 | T4: Average Daily Market Returns | U4: =AVERAGE(Q3:Q1241) -> 0.00050461517 | V4: =AVERAGE(Q3:Q1241) -> 0.00050461517
A5: 44202 | B5: 30.9 | C5: =(B5-B4)/B4 -> -0.03286385 | D5: =(B5-B4)/B4 -> -0.03286385 | E5: Average Daily Stock Returns | F5: =AVERAGE(C3:C1241) -> 0.0026696663 | G5: =AVERAGE(C3:C1241) -> 0.0026696663 | O5: 44202 | P5: 48174.06 | Q5: =(P5-P4)/P4 -> -0.0054445105 | R5: =(P5-P4)/P4 -> -0.0054445105 | T5: Standard Deviation of daily Market Returns | U5: =_xlfn.STDEV.S(Q3:Q1241) -> 0.0088282244 | V5: =_xlfn.STDEV.S(Q3:Q1241) -> 0.0088282244
A6: 44203 | B6: 33.9 | C6: =(B6-B5)/B5 -> 0.097087379 | D6: =(B6-B5)/B5 -> 0.097087379 | E6: Standard Deviation of daily Stock Returns | F6: =_xlfn.STDEV.S(C3:C1241) -> 0.039014628 | G6: =_xlfn.STDEV.S(C3:C1241) -> 0.039014628 | O6: 44203 | P6: 48093.32 | Q6: =(P6-P5)/P5 -> -0.0016760057 | R6: =(P6-P5)/P5 -> -0.0016760057 | Y6: Covariance between the stock returns and market returns | Z6: =_xlfn.COVARIANCE.S(C3:C1241,Q3:Q1241) -> 7.329155e-05
A7: 44204 | B7: 33.05 | C7: =(B7-B6)/B6 -> -0.025073746 | D7: =(B7-B6)/B6 -> -0.025073746 | O7: 44204 | P7: 48782.51 | Q7: =(P7-P6)/P6 -> 0.014330265 | R7: =(P7-P6)/P6 -> 0.014330265 | Y7: Correlation coefficient between the stock returns and market returns | Z7: =CORREL(C3:C1241,Q3:Q1241) -> 0.21279091
A8: 44207 | B8: 32.85 | C8: =(B8-B7)/B7 -> -0.0060514372 | D8: =(B8-B7)/B7 -> -0.0060514372 | O8: 44207 | P8: 49269.32 | Q8: =(P8-P7)/P7 -> 0.0099791913 | R8: =(P8-P7)/P7 -> 0.0099791913 | T8: Market Return | U8: Daily Market Return | V8: Annualized Daily Return
A9: 44208 | B9: 32.05 | C9: =(B9-B8)/B8 -> -0.02435312 | D9: =(B9-B8)/B8 -> -0.02435312 | H9: Stock Return | I9: Daiy Stock Return | J9: Annualized daily Return | O9: 44208 | P9: 49517.11 | Q9: =(P9-P8)/P8 -> 0.0050292961 | R9: =(P9-P8)/P8 -> 0.0050292961 | T9: year1 01-01-21 to 31-12-21 | U9: =AVERAGE(Q3:Q249) -> 0.00084485719 | V9: =(1+U9)^252-1 -> 0.23715467
A10: 44209 | B10: 31.2 | C10: =(B10-B9)/B9 -> -0.026521061 | D10: =(B10-B9)/B9 -> -0.026521061 | H10: year1 01-01-21 to 31-12-21 | I10: =AVERAGE(C3:C249) -> 0.0046625504 | J10: =(1+I10)^252-1 -> 2.2291922 | O10: 44209 | P10: 49492.32 | Q10: =(P10-P9)/P9 -> -0.00050063503 | R10: =(P10-P9)/P9 -> -0.00050063503 | T10: year 2 01-01-22 to 31-12-22 | U10: =AVERAGE(Q250:Q497) -> 0.00023578935 | V10: =(1+U10)^252-1 -> 0.061212276 | AO10: E(Ri​) = Expected return of the company
A11: 44210 | B11: 29.75 | C11: =(B11-B10)/B10 -> -0.046474359 | D11: =(B11-B10)/B10 -> -0.046474359 | H11: year 2 01-01-22 to 31-12-22 | I11: =AVERAGE(C250:C497) -> 0.003715865 | J11: =(1+I11)^252-1 -> 1.5463539 | O11: 44210 | P11: 49584.16 | Q11: =(P11-P10)/P10 -> 0.0018556414 | R11: =(P11-P10)/P10 -> 0.0018556414 | T11: year 3 01-01-23 to 31-12-23 | U11: =AVERAGE(Q498:Q743) -> 0.00071776648 | V11: =(1+U11)^252-1 -> 0.19819022 | AO11: Rf​ = Risk-free rate = 6.72%
A12: 44211 | B12: 29.25 | C12: =(B12-B11)/B11 -> -0.016806723 | D12: =(B12-B11)/B11 -> -0.016806723 | H12: year 3 01-01-23 to 31-12-23 | I12: =AVERAGE(C498:C743) -> 0.0039596794 | J12: =(1+I12)^252-1 -> 1.7070753 | O12: 44211 | P12: 49034.67 | Q12: =(P12-P11)/P11 -> -0.011081966 | R12: =(P12-P11)/P11 -> -0.011081966 | T12: year 4 01-01-24 to 31-12-24 | U12: =AVERAGE(Q744:Q992) -> 0.00035357753 | V12: =(1+U12)^252-1 -> 0.093174435 | AI12: E(Ri​)=Rf​+βi​(Rm​−Rf​)​ | AL12: Rf​ = Risk-free rate = 6.72% | AO12: βi​ = Beta of the company
A13: 44214 | B13: 29.1 | C13: =(B13-B12)/B12 -> -0.0051282051 | D13: =(B13-B12)/B12 -> -0.0051282051 | H13: year 4 01-01-24 to 31-12-24 | I13: =AVERAGE(C744:C992) -> 0.0038448172 | J13: =(1+I13)^252-1 -> 1.6301374 | O13: 44214 | P13: 48564.27 | Q13: =(P13-P12)/P12 -> -0.0095932123 | R13: =(P13-P12)/P12 -> -0.0095932123 | T13: year 5 01-01-25 to 31-12-25 | U13: =AVERAGE(Q993:Q1241) -> 0.00037530667 | V13: =(1+U13)^252-1 -> 0.099174603 | AN13: 0.0672 | AO13: Rm​ = Annual market return
A14: 44215 | B14: 30.2 | C14: =(B14-B13)/B13 -> 0.037800687 | D14: =(B14-B13)/B13 -> 0.037800687 | H14: year 5 01-01-25 to 31-12-25 | I14: =AVERAGE(C994:C1242) -> -0.0028500384 | J14: =(1+I14)^252-1 -> -0.51287528 | O14: 44215 | P14: 49398.29 | Q14: =(P14-P13)/P13 -> 0.017173531 | R14: =(P14-P13)/P13 -> 0.017173531
A15: 44216 | B15: 30.15 | C15: =(B15-B14)/B14 -> -0.0016556291 | D15: =(B15-B14)/B14 -> -0.0016556291 | O15: 44216 | P15: 49792.12 | Q15: =(P15-P14)/P14 -> 0.0079725432 | R15: =(P15-P14)/P14 -> 0.0079725432 | AO15: E(Ri​)=Rf​+βi​(Rm​−Rf​)​
A16: 44217 | B16: 29 | C16: =(B16-B15)/B15 -> -0.03814262 | D16: =(B16-B15)/B15 -> -0.03814262 | O16: 44217 | P16: 49624.76 | Q16: =(P16-P15)/P15 -> -0.0033611744 | R16: =(P16-P15)/P15 -> -0.0033611744 | AI16: Years | AJ16: Beta | AK16: Interpretation | AM16: Annualized Market Return | AO16: Annualized Stock Return | AQ16: CAPM Expected | AR16: Interpretation
A17: 44218 | B17: 27.8 | C17: =(B17-B16)/B16 -> -0.04137931 | D17: =(B17-B16)/B16 -> -0.04137931 | O17: 44218 | P17: 48878.54 | Q17: =(P17-P16)/P16 -> -0.015037252 | R17: =(P17-P16)/P16 -> -0.015037252 | AI17: 2021 | AJ17: =_xlfn.COVARIANCE.S(C3:C249,Q3:Q249)/_xlfn.VAR.S(Q3:Q249) -> 0.59135391 | AK17: Lower market sensitivity | AM17: =V9 -> 0.23715467 | AO17: =J10 -> 2.2291922 | AQ17: =$AN$13 + AJ17 * (AM17 - $AN$13) -> 0.16770336 | AR17: Above
A18: 44221 | B18: 27.05 | C18: =(B18-B17)/B17 -> -0.026978417 | D18: =(B18-B17)/B17 -> -0.026978417 | O18: 44221 | P18: 48347.59 | Q18: =(P18-P17)/P17 -> -0.01086264 | R18: =(P18-P17)/P17 -> -0.01086264 | AI18: 2022 | AJ18: =_xlfn.COVARIANCE.S(C250:C497,Q250:Q497)/_xlfn.VAR.S(Q250:Q497) -> 0.85889437 | AK18: Lower market sensitivity | AM18: =V10 -> 0.061212276 | AO18: =J11 -> 1.5463539 | AQ18: =$AN$13 + AJ18 * (AM18 - $AN$13) -> 0.062057177 | AR18: Above
A19: 44223 | B19: 28.35 | C19: =(B19-B18)/B18 -> 0.04805915 | D19: =(B19-B18)/B18 -> 0.04805915 | O19: 44223 | P19: 47409.93 | Q19: =(P19-P18)/P18 -> -0.019394141 | R19: =(P19-P18)/P18 -> -0.019394141 | AI19: 2023 | AJ19: =_xlfn.COVARIANCE.S(C498:C743,Q498:Q743)/_xlfn.VAR.S(Q498:Q743) -> 0.73274519 | AK19: Lower market sensitivity | AM19: =V11 -> 0.19819022 | AO19: =J12 -> 1.7070753 | AQ19: =$AN$13 + AJ19 * (AM19 - $AN$13) -> 0.16318245 | AR19: Above
A20: 44224 | B20: 27.65 | C20: =(B20-B19)/B19 -> -0.024691358 | D20: =(B20-B19)/B19 -> -0.024691358 | O20: 44224 | P20: 46874.36 | Q20: =(P20-P19)/P19 -> -0.011296579 | R20: =(P20-P19)/P19 -> -0.011296579 | AI20: 2024 | AJ20: =_xlfn.COVARIANCE.S(C744:C992,Q744:Q992)/_xlfn.VAR.S(Q744:Q992) -> 1.0117773 | AK20: Approximately same sensitivity as market | AM20: =V12 -> 0.093174435 | AO20: =J13 -> 1.6301374 | AQ20: =$AN$13 + AJ20 * (AM20 - $AN$13) -> 0.093480344 | AR20: Above
A21: 44225 | B21: 28.1 | C21: =(B21-B20)/B20 -> 0.016274864 | D21: =(B21-B20)/B20 -> 0.016274864 | O21: 44225 | P21: 46285.77 | Q21: =(P21-P20)/P20 -> -0.012556758 | R21: =(P21-P20)/P20 -> -0.012556758 | AI21: 2025 | AJ21: =_xlfn.COVARIANCE.S(C993:C1241,Q993:Q1241)/_xlfn.VAR.S(Q993:Q1241) -> 1.7914054 | AK21: Much higher market sensitivity | AM21: =V13 -> 0.099174603 | AO21: =J14 -> -0.51287528 | AQ21: =$AN$13 + AJ21 * (AM21 - $AN$13) -> 0.12447948 | AR21: Below
A22: 44228 | B22: 28.2 | C22: =(B22-B21)/B21 -> 0.0035587189 | D22: =(B22-B21)/B21 -> 0.0035587189 | O22: 44228 | P22: 48600.61 | Q22: =(P22-P21)/P21 -> 0.050011915 | R22: =(P22-P21)/P21 -> 0.050011915
A23: 44229 | B23: 28.2 | C23: =(B23-B22)/B22 -> 0 | D23: =(B23-B22)/B22 -> 0 | O23: 44229 | P23: 49797.72 | Q23: =(P23-P22)/P22 -> 0.024631584 | R23: =(P23-P22)/P22 -> 0.024631584
A24: 44230 | B24: 27.95 | C24: =(B24-B23)/B23 -> -0.0088652482 | D24: =(B24-B23)/B23 -> -0.0088652482 | O24: 44230 | P24: 50255.75 | Q24: =(P24-P23)/P23 -> 0.0091978107 | R24: =(P24-P23)/P23 -> 0.0091978107
A25: 44231 | B25: 28.5 | C25: =(B25-B24)/B24 -> 0.019677996 | D25: =(B25-B24)/B24 -> 0.019677996 | O25: 44231 | P25: 50614.29 | Q25: =(P25-P24)/P24 -> 0.007134308 | R25: =(P25-P24)/P24 -> 0.007134308
A26: 44232 | B26: 28.3 | C26: =(B26-B25)/B25 -> -0.0070175439 | D26: =(B26-B25)/B25 -> -0.0070175439 | O26: 44232 | P26: 50731.63 | Q26: =(P26-P25)/P25 -> 0.0023183176 | R26: =(P26-P25)/P25 -> 0.0023183176
A27: 44235 | B27: 30.25 | C27: =(B27-B26)/B26 -> 0.068904594 | D27: =(B27-B26)/B26 -> 0.068904594 | O27: 44235 | P27: 51348.77 | Q27: =(P27-P26)/P26 -> 0.012164797 | R27: =(P27-P26)/P26 -> 0.012164797
A28: 44236 | B28: 30.25 | C28: =(B28-B27)/B27 -> 0 | D28: =(B28-B27)/B27 -> 0 | O28: 44236 | P28: 51329.08 | Q28: =(P28-P27)/P27 -> -0.00038345612 | R28: =(P28-P27)/P27 -> -0.00038345612
A29: 44237 | B29: 28.8 | C29: =(B29-B28)/B28 -> -0.047933884 | D29: =(B29-B28)/B28 -> -0.047933884 | O29: 44237 | P29: 51309.39 | Q29: =(P29-P28)/P28 -> -0.00038360321 | R29: =(P29-P28)/P28 -> -0.00038360321
A30: 44238 | B30: 29.9 | C30: =(B30-B29)/B29 -> 0.038194444 | D30: =(B30-B29)/B29 -> 0.038194444 | O30: 44238 | P30: 51531.52 | Q30: =(P30-P29)/P29 -> 0.0043292271 | R30: =(P30-P29)/P29 -> 0.0043292271
A31: 44239 | B31: 29.65 | C31: =(B31-B30)/B30 -> -0.008361204 | D31: =(B31-B30)/B30 -> -0.008361204 | O31: 44239 | P31: 51544.3 | Q31: =(P31-P30)/P30 -> 0.00024800355 | R31: =(P31-P30)/P30 -> 0.00024800355
A32: 44242 | B32: 27.25 | C32: =(B32-B31)/B31 -> -0.080944351 | D32: =(B32-B31)/B31 -> -0.080944351 | O32: 44242 | P32: 52154.13 | Q32: =(P32-P31)/P31 -> 0.011831182 | R32: =(P32-P31)/P31 -> 0.011831182
A33: 44243 | B33: 26.45 | C33: =(B33-B32)/B32 -> -0.029357798 | D33: =(B33-B32)/B32 -> -0.029357798 | O33: 44243 | P33: 52104.17 | Q33: =(P33-P32)/P32 -> -0.00095792989 | R33: =(P33-P32)/P32 -> -0.00095792989
... A1241: 46022 | B1241: 334 | C1241: =(B1241-B1240)/B1240 -> -0.0028362442 | D1241: =(B1241-B1240)/B1240 -> -0.0028362442 | O1241: 46022 | P1241: 85220.6 | Q1241: =(P1241-P1240)/P1240 -> 0.0064425094 | R1241: =(P1241-P1240)/P1240 -> 0.0064425094

Sheet Market Returns 
A1: Date | B1: Close Price | C1: Daily Market Returns | D1: Daily Market Returns%
A2: 44197 | B2: 47868.98 | C2: -
A3: 44200 | B3: 48176.8 | C3: =(B3-B2)/B2 -> 0.0064304692 | D3: =(B3-B2)/B2 -> 0.0064304692 | G3: Returns | H3: Returns%
A4: 44201 | B4: 48437.78 | C4: =(B4-B3)/B3 -> 0.0054171302 | D4: =(B4-B3)/B3 -> 0.0054171302 | F4: Average Daily Market Returns | G4: =AVERAGE(C3:C1241) -> 0.00050461517 | H4: =AVERAGE(C3:C1241) -> 0.00050461517
A5: 44202 | B5: 48174.06 | C5: =(B5-B4)/B4 -> -0.0054445105 | D5: =(B5-B4)/B4 -> -0.0054445105 | F5: Standard Deviation of daily Market Returns | G5: =_xlfn.STDEV.S(C3:C1241) -> 0.0088282244 | H5: =_xlfn.STDEV.S(C3:C1241) -> 0.0088282244
A6: 44203 | B6: 48093.32 | C6: =(B6-B5)/B5 -> -0.0016760057 | D6: =(B6-B5)/B5 -> -0.0016760057
A7: 44204 | B7: 48782.51 | C7: =(B7-B6)/B6 -> 0.014330265 | D7: =(B7-B6)/B6 -> 0.014330265
A8: 44207 | B8: 49269.32 | C8: =(B8-B7)/B7 -> 0.0099791913 | D8: =(B8-B7)/B7 -> 0.0099791913 | F8: Market Return | G8: Daily Market Return | H8: Annualized Daily Return
A9: 44208 | B9: 49517.11 | C9: =(B9-B8)/B8 -> 0.0050292961 | D9: =(B9-B8)/B8 -> 0.0050292961 | F9: year1 01-01-21 to 31-12-21 | G9: =AVERAGE(C3:C249) -> 0.00084485719 | H9: =(1+G9)^252-1 -> 0.23715467
A10: 44209 | B10: 49492.32 | C10: =(B10-B9)/B9 -> -0.00050063503 | D10: =(B10-B9)/B9 -> -0.00050063503 | F10: year 2 01-01-22 to 31-12-22 | G10: =AVERAGE(C250:C497) -> 0.00023578935 | H10: =(1+G10)^252-1 -> 0.061212276
A11: 44210 | B11: 49584.16 | C11: =(B11-B10)/B10 -> 0.0018556414 | D11: =(B11-B10)/B10 -> 0.0018556414 | F11: year 3 01-01-23 to 31-12-23 | G11: =AVERAGE(C498:C743) -> 0.00071776648 | H11: =(1+G11)^252-1 -> 0.19819022
A12: 44211 | B12: 49034.67 | C12: =(B12-B11)/B11 -> -0.011081966 | D12: =(B12-B11)/B11 -> -0.011081966 | F12: year 4 01-01-24 to 31-12-24 | G12: =AVERAGE(C744:C992) -> 0.00035357753 | H12: =(1+G12)^252-1 -> 0.093174435
A13: 44214 | B13: 48564.27 | C13: =(B13-B12)/B12 -> -0.0095932123 | D13: =(B13-B12)/B12 -> -0.0095932123 | F13: year 5 01-01-25 to 31-12-25 | G13: =AVERAGE(C993:C1241) -> 0.00037530667 | H13: =(1+G13)^252-1 -> 0.099174603
A14: 44215 | B14: 49398.29 | C14: =(B14-B13)/B13 -> 0.017173531 | D14: =(B14-B13)/B13 -> 0.017173531
A15: 44216 | B15: 49792.12 | C15: =(B15-B14)/B14 -> 0.0079725432 | D15: =(B15-B14)/B14 -> 0.0079725432
A16: 44217 | B16: 49624.76 | C16: =(B16-B15)/B15 -> -0.0033611744 | D16: =(B16-B15)/B15 -> -0.0033611744
A17: 44218 | B17: 48878.54 | C17: =(B17-B16)/B16 -> -0.015037252 | D17: =(B17-B16)/B16 -> -0.015037252
A18: 44221 | B18: 48347.59 | C18: =(B18-B17)/B17 -> -0.01086264 | D18: =(B18-B17)/B17 -> -0.01086264
A19: 44223 | B19: 47409.93 | C19: =(B19-B18)/B18 -> -0.019394141 | D19: =(B19-B18)/B18 -> -0.019394141
A20: 44224 | B20: 46874.36 | C20: =(B20-B19)/B19 -> -0.011296579 | D20: =(B20-B19)/B19 -> -0.011296579
A21: 44225 | B21: 46285.77 | C21: =(B21-B20)/B20 -> -0.012556758 | D21: =(B21-B20)/B20 -> -0.012556758
A22: 44228 | B22: 48600.61 | C22: =(B22-B21)/B21 -> 0.050011915 | D22: =(B22-B21)/B21 -> 0.050011915
A23: 44229 | B23: 49797.72 | C23: =(B23-B22)/B22 -> 0.024631584 | D23: =(B23-B22)/B22 -> 0.024631584
A24: 44230 | B24: 50255.75 | C24: =(B24-B23)/B23 -> 0.0091978107 | D24: =(B24-B23)/B23 -> 0.0091978107
A25: 44231 | B25: 50614.29 | C25: =(B25-B24)/B24 -> 0.007134308 | D25: =(B25-B24)/B24 -> 0.007134308
... A1241: 46022 | B1241: 85220.6 | C1241: =(B1241-B1240)/B1240 -> 0.0064425094 | D1241: =(B1241-B1240)/B1240 -> 0.0064425094

Sheet Coveriance and Correlation
A1: Covariance between the stock returns and market returns | B1: =_xlfn.COVARIANCE.S('Stock Returns'!C3:C1241,'Market Returns '!C3:C1241) -> 7.329155e-05
A2: Correlation coefficient between the stock returns and market returns | B2: =CORREL('Stock Returns'!C3:C1241,'Market Returns '!C3:C1241) -> 0.21279091

Sheet Beta
A1: 5 Year Beta | B1: =_xlfn.COVARIANCE.S('Stock Returns'!C3:C1241,'Market Returns '!C3:C1241)/_xlfn.VAR.S('Market Returns '!C3:C1241) -> 0.94038821 | D1: βi​ - | E1: COVARIANCE.S(Company_Returns,Market_Returns)/VAR.S(Market_Returns) | M1: For 5 years
A3: This means Dynamic Cables Ltd. has slightly lower systematic risk than the market.
A5: β = 1 → moves approximately in line with the market
A6: β > 1 → more sensitive/risky than the market
A7: β < 1 → less sensitive than the market
A8: β = 0.94 → if the market moves by 1%, Dynamic Cables would theoretically be expected to move by about 0.94% in the same direction, on average.
A10: So we can say that:
A12: Dynamic Cables Ltd. has a beta of approximately 0.94, indicating that the stock has slightly lower systematic risk than the market. movements is slightly lower.
A13: The stock tends to move in the same direction as the market, but its sensitivity to market

Sheet 5 years Beta
A1: E(Ri​)=Rf​+βi​(Rm​−Rf​)​ | D1: Rf​ = Risk-free rate = 6.72%
A5: Years | B5: Beta | C5: Interpretation | G5: Annualized Market Return | I5: Annualized Stock Return
A6: 2021 | B6: =_xlfn.COVARIANCE.S('Stock Returns'!C3:C249,'Market Returns '!C3:C249)/_xlfn.VAR.S('Market Returns '!C3:C249) -> 0.59135391 | C6: Lower market sensitivity | G6: ='Market Returns '!H9 -> 0.23715467 | I6: ='Stock Returns'!J10 -> 2.2291922
A7: 2022 | B7: =CAPM!B19 -> 0.85889437 | C7: Lower market sensitivity | G7: ='Market Returns '!H10 -> 0.061212276 | I7: ='Stock Returns'!J11 -> 1.5463539
A8: 2023 | B8: =CAPM!B20 -> 0.73274519 | C8: Lower market sensitivity | G8: ='Market Returns '!H11 -> 0.19819022 | I8: ='Stock Returns'!J12 -> 1.7070753
A9: 2024 | B9: =_xlfn.COVARIANCE.S('Stock Returns'!C744:C992,'Market Returns '!C744:C992)/_xlfn.VAR.S('Market Returns '!C744:C992) -> 1.0117773 | C9: Approximately same sensitivity as market | G9: ='Market Returns '!H12 -> 0.093174435 | I9: ='Stock Returns'!J13 -> 1.6301374
A10: 2025 | B10: =_xlfn.COVARIANCE.S('Stock Returns'!C993:C1241,'Market Returns '!C993:C1241)/_xlfn.VAR.S('Market Returns '!C993:C1241) -> 1.7914054 | C10: Much higher market sensitivity | G10: ='Market Returns '!H13 -> 0.099174603 | I10: ='Stock Returns'!J14 -> -0.51287528

Sheet CAPM
F1: E(Ri​) = Expected return of the company
F2: Rf​ = Risk-free rate = 6.72%
F3: βi​ = Beta of the company
F4: Rm​ = Annual market return
A5: 1. Capital Asset Pricing Model (CAPM) With 5 year Beta | D5: 0.0672
A7: E(Ri​)=Rf​+βi​(Rm​−Rf​)​
A16: Capital Asset Pricing Model (CAPM) With Per year Beta for 5 years
A17: Year | B17: Beta | C17: Annualized Stock Return | E17: Annualized Market Return | F17: Annualized Market Return % | H17: CAPM Expected | I17: Interpretation
A18: Year 1 | B18: =_xlfn.COVARIANCE.S('Stock Returns'!C3:C249,'Market Returns '!C3:C249)/_xlfn.VAR.S('Market Returns '!C3:C249) -> 0.59135391 | C18: ='Stock Returns'!J10 -> 2.2291922 | E18: ='Market Returns '!H9 -> 0.23715467 | F18: =E18 -> 0.23715467 | H18: =$D$5+B18*(CAPM!E18-CAPM!D5) -> 0.16770336 | I18: Above
A19: Year 2 | B19: =_xlfn.COVARIANCE.S('Stock Returns'!C250:C497,'Market Returns '!C250:C497)/_xlfn.VAR.S('Market Returns '!C250:C497) -> 0.85889437 | C19: ='Stock Returns'!J11 -> 1.5463539 | E19: ='Market Returns '!H10 -> 0.061212276 | F19: =E19 -> 0.061212276 | H19: =$D$5+B19*(CAPM!E19-CAPM!D5) -> 0.062057177 | I19: Above
A20: Year 3 | B20: =_xlfn.COVARIANCE.S('Stock Returns'!C498:C743,'Market Returns '!C498:C743)/_xlfn.VAR.S('Market Returns '!C498:C743) -> 0.73274519 | C20: ='Stock Returns'!J12 -> 1.7070753 | E20: ='Market Returns '!H11 -> 0.19819022 | F20: =E20 -> 0.19819022 | H20: =$D$5+B20*(CAPM!E20-CAPM!D5) -> 0.16318245 | I20: Above
A21: Year 4 | B21: =_xlfn.COVARIANCE.S('Stock Returns'!C744:C992,'Market Returns '!C744:C992)/_xlfn.VAR.S('Market Returns '!C744:C992) -> 1.0117773 | C21: ='Stock Returns'!J13 -> 1.6301374 | E21: ='Market Returns '!H12 -> 0.093174435 | F21: =E21 -> 0.093174435 | H21: =$D$5+B21*(CAPM!E21-CAPM!D5) -> 0.093480344 | I21: Above
A22: Year 5 | B22: =_xlfn.COVARIANCE.S('Stock Returns'!C993:C1241,'Market Returns '!C993:C1241)/_xlfn.VAR.S('Market Returns '!C993:C1241) -> 1.7914054 | C22: ='Stock Returns'!J14 -> -0.51287528 | E22: ='Market Returns '!H13 -> 0.099174603 | F22: =E22 -> 0.099174603 | H22: =$D$5+B22*(CAPM!E22-CAPM!D5) -> 0.12447948 | I22: Below
